Workbook

Sheet 표지
B6: TDS 버전 : | C6: 1.4.13.43 | I6: 완료 일자 : | K6: 46240
B8: 1. 문서 번호
B9: 문서 번호 | D9: TDS-SQC-2026-007
B12: 2. 작업자
B13: PLC | D13: 정충영 | G13: 문자열, 다국어 | I13: 김현상
B14: TOP-VIEW | D14: 정충영 | G14: 보안 | I14: 안소희
B15: 경보 | D15: 김현상 | G15: 전송 | I15: 안소희
B16: 로그 | D16: 김현상 | G16: VNC, FTP, 기타 | I16: 안소희
B17: 레시피 | D17: 김현상
B19: 3. 테스트 모델
B20: No | D20: HMI | G20: No | I20: PLC
B21: 1 | D21: TOPRT1550W | G21: 1 | I21: Siemens S7-1500
B22: 2 | D22: TOPRX0800S | G22: 2 | I22: Mitsubishi Q
B23: 3 | D23: TOP-VIEW | G23: 3 | I23: LS XBC
B24: 4 | D24: TOPRD1240+TOPRP50D | G24: 4 | I24: LS XBM
B25: 5 | G25: 5
B27: 4. 테스트 결과 요약
B28: 정상 동작 | D28: =('테스트 결과'!J13) -> 0
B29: 이상 발견 | D29: =('테스트 결과'!G14) -> 0
B30: 개선 필요 | D30: =('테스트 결과'!H14) -> 0.01744186
B32: 5. 검토
B33: 담당 부서 | D33: 테크니컬팀
B34: 배포 일정 | D34: -

Sheet TOP-VIEW
B2: 테스트 모델 | C2: TOPRT1550W, TOP-VIEW | F2: 정상 동작 | G2: 이상 발견 | H2: 개선 필요
B3: TDS 버전 | C3: =(표지!C6) -> 1.4.13.43 | F3: =IF(G2<>"", TEXT(COUNTIF(G9:G9933, "*" & F2 & "*") / COUNTA(A9:A933), "0.0%"), "") -> 0.0% | G3: =IF(G2<>"", TEXT(COUNTIF(G9:G9934, "*" & G2 & "*") / COUNTA(A9:A9934), "0.0%"), "") -> 0.0% | H3: =IF(H2<>"", TEXT(COUNTIF(G9:G9934, "*" & H2 & "*") / COUNTA(A9:A9934), "0.0%"), "") -> 5.3%
B4: 테스트 일자 | C4: 46239 | F4: 테스트 완료
B5: 작업자 | C5: =(표지!D14) -> 정충영 | F5: =TEXT(COUNTA(G9:G9933) / COUNTA(A9:A9934), "0.0%") -> 5.3%
A7: No | B7: 카테고리 | C7: 항목 | D7: 테스트 동작 | E7: 기대 결과 | G7: 테스트 결과 | H7: 비고
A9: 1 | B9: TOP-VIEW | C9: 보고서 | D9: 폼 보고서 | E9: 폼 보고서 생성
A10: 2 | D10: 리스트 보고서 | E10: 리스트 보고서 생성
A11: 3 | D11: 자유양식 보고서 | E11: 자유양식 보고서 생성
A12: 4 | D12: 데이터베이스 보고서 | E12: 데이터베이스 보고서 생성
A13: 5 | C13: 내부 DB | D13: 21 CFR Part 11 - 암호화 | E13: 외부 DB로 부터 데이터 접근 제한
A14: 6 | D14: 21 CFR Part 11 - 내보내기 PDF 변환 | E14: DB 뷰어에 PDF 내보내기 활성화
A15: 7 | D15: 21 CFR Part 11 - 데이터베이스 이중화 | E15: 설정 경로 DB 파일 생성
A16: 8 | D16: 21 CFR Part 11 - 결제란 추가 | E16: DB 뷰어 PDF 내보내기 시, 결제란 추가
A17: 9 | D17: 데이터베이스 동기화 | E17: 데이터베이스 동기화
A18: 10 | D18: 보안 로그 컬럼 커스텀 기능 | E18: 보안 로그 컬럼 커스텀을 통한 조회 여부
A19: 11 | D19: 데이터베이스 - GlobalLog - 테이블 | E19: 테이블 기능을 통한 로그 테이블 조회
A20: 12 | D20: 데이터베이스 - GlobalLog - 쿼리 | E20: 쿼리 기능을 통한 로그 평균값 조회
A21: 13 | D21: 데이터베이스 - GlobalAlarm - 테이블 | E21: 테이블 기능을 통한 경보 테이블 조회
A22: 14 | D22: 데이터베이스 - GlobalAlarm - 쿼리 | E22: 쿼리 기능을 통한 경보 평균값 조회
A23: 15 | C23: 외부 DB | D23: 데이터베이스 테이블 오브젝트 - 키 - Search | E23: 외부 DB 테이블 조회
A24: 16 | D24: 데이터베이스 테이블 오브젝트 - 키 - Add | E24: 외부 DB 테이블 데이터 삽입
A25: 17 | D25: 데이터베이스 테이블 오브젝트 - 키 - Modify | E25: 외부 DB 테이블 데이터 수정
A26: 18 | D26: 데이터베이스 테이블 오브젝트 - 키 - Delete | E26: 외부 DB 테이블 데이터 삭제
A27: 19 | D27: 데이터베이스 테이블 오브젝트 - 키 - Export | E27: 외부 DB 테이블 데이터 내보내기
A28: 20 | D28: 데이터베이스 - 쿼리 - 조회 | E28: 쿼리 기능을 통한 외부 DB 데이터 조회
A29: 21 | D29: 데이터베이스 - 쿼리 - 삽입 | E29: 쿼리 기능을 통한 외부 DB 데이터 삽입
A30: 22 | D30: 데이터베이스 - 쿼리 - 수정 | E30: 쿼리 기능을 통한 외부 DB 데이터 수정
A31: 23 | D31: 데이터베이스 - 쿼리 - 삭제 | E31: 쿼리 기능을 통한 외부 DB 데이터 삭제
A32: 24 | D32: 데이터베이스 - 완료 비트 | E32: DB 동작 성공 시 설정 비트 ON
A33: 25 | D33: 데이터베이스 - 실행 결과 | E33: DB 동작 성공 시 설정 워드 값 1
A34: 26 | D34: HMI - 교환 서버 - 조회 | E34: TOP-VIEW를 통한 외부 DB 데이터 조회
A35: 27 | D35: HMI - 교환 서버 - 삽입 | E35: TOP-VIEW를 통한 외부 DB 데이터 삽입
... A37: 29 | D37: HMI - 교환 서버 - 삭제 | E37: TOP-VIEW를 통한 외부 DB 데이터 삭제
A38: 30 | C38: OPC UA 서버 → 클라이언트 | D38: OPC UA Bit 데이터 통신 | E38: Bit 데이터 정상 통신
A39: 31 | D39: OPC UA Word 데이터 통신 | E39: Word 데이터 정상 통신
A40: 32 | D40: OPC UA Float 데이터 통신 | E40: Float 데이터 정상 통신
A41: 33 | D41: OPC UA Ascii 데이터 통신 | E41: Ascii 데이터 정상 통신
A42: 34 | D42: OPC UA Word 배열 데이터 통신 | E42: Word 배열 데이터 정상 통신
A43: 35 | D43: OPC UA Float 배열 데이터 통신 | E43: Float 배열 데이터 정상 통신
A44: 36 | D44: OPC UA Ascii 배열 데이터 통신 | E44: Ascii 배열 데이터 정상 통신
...

Sheet PLC
B2: 테스트 모델 | C2: TOPRT1550W, TOPRX0800S | D2: N:N 통신 구성 | F2: 정상 동작 | G2: 이상 발견 | H2: 개선 필요
B3: TDS 버전 | C3: =(표지!C6) -> 1.4.13.43 | D3: ipTIME ↔ 허브 ↔ HMI(MBUS Server) ↔ HMI(MBUS Clinet) EtherNet PLC(Siemens S7-1500, Mitsubishi Q) + Serial PLC(LS XBC) | F3: =IF(G2<>"", TEXT(COUNTIF(G9:G9942, "*" & F2 & "*") / COUNTA(A9:A942), "0.0%"), "") -> 0.0% | G3: =IF(G2<>"", TEXT(COUNTIF(G9:G9943, "*" & G2 & "*") / COUNTA(A9:A9943), "0.0%"), "") -> 0.0% | H3: =IF(H2<>"", TEXT(COUNTIF(G9:G9943, "*" & H2 & "*") / COUNTA(A9:A9943), "0.0%"), "") -> 6.1%
B4: 테스트 일자 | C4: 46239 | F4: 테스트 완료
B5: 작업자 | C5: =(표지!D13) -> 정충영 | F5: =TEXT(COUNTA(G9:G9942) / COUNTA(A9:A9943), "0.0%") -> 6.1%
A7: No | B7: 카테고리 | C7: 항목 | D7: 테스트 동작 | E7: 기대 결과 | G7: 테스트 결과 | H7: 비고
A9: 1 | B9: PLC | C9: DHCP | D9: DHCP IP 할당 | E9: DHCP 설정된 IP 영역 자동 할당 | G9: 개선 필요 | H9: #22944
A10: 2 | D10: 브릿지 모드 DHCP IP 할당 | E10: 브릿지 모드 상태에서 DHCP 설정된 IP 영역 자동 할당 | G10: 개선 필요 | H10: #22944
A11: 3 | C11: 동기화 | D11: PLC 주소로 부터 화면 번호 쓰기 | E11: 설정 주소를 통한 HMI 화면 제어
A12: 4 | D12: PLC 주소로 부터 화면 번호 읽기 | E12: 설정 주소에 HMI 화면 번호 표시
A13: 5 | D13: PLC 날짜/시간 동기화 | E13: PLC 주소로 부터 HMI 시간 변경
A14: 6 | D14: HMI 날짜/시간 동기화 | E14: HMI 주소로 PLC 시간 주소 변경
A15: 7 | D15: 프로젝트 설정 - PLC 버퍼 동기화 읽기 동작 | E15: 연속된 PLC Word 데이터 읽기 정상
A16: 8 | D16: 프로젝트 설정 - PLC 버퍼 동기화 쓰기 동작 | E16: 연속된 내부 주소 Word 데이터 쓰기 정상
A17: 9 | C17: 심볼 | D17: 시리얼 PLC 심볼 + 통신 블록 통신 | E17: 통신 블록에 설정한 주기로 PLC 데이터 통신 정상
A18: 10 | D18: 주소 기반 PLC 심볼 + 통신 블록 통신 | E18: 통신 블록에 설정한 주기로 PLC 데이터 통신 정상
A19: 11 | D19: 변수 기반 PLC 심볼 + 통신 블록 통신 | E19: 통신 블록에 설정한 주기로 PLC 데이터 통신 정상
A20: 12 | D20: 변수 기반 PLC 배열 심볼 + 통신 블록 통신 | E20: 통신 블록에 설정한 주기로 PLC 데이터 통신 정상
A21: 13 | C21: 특수 주소 | D21: 특수 주소 - COMM_ENET_STATUS | E21: 0:정상, 1:타임아웃 정상 표시
A22: 14 | D22: 특수 주소 - COMM_SERIAL_STATUS | E22: 0:정상, 1:타임아웃 정상 표시
A23: 15 | D23: 특수 주소 - ETH1_CABLE_STATUS | E23: 0:연결안됨, 1:연결됨 정상 표시
A24: 16 | D24: 특수 주소 - ERROR_ENET_IP1 | E24: 통신 에러 PLC IP 주소 표시
A25: 17 | C25: 특수 기능 | D25: 특수 기능 - PLC Enable (Serial PLC) | E25: Serial PLC 활성화
A26: 18 | D26: 특수 기능 - PLC Disable (Serial PLC) | E26: Serial PLC 비활성화
A27: 19 | D27: 특수 기능 - PLC Enable (Mitsubishi PLC) | E27: Mitsubishi PLC 활성화
A28: 20 | D28: 특수 기능 - PLC Disable (Mitsubishi PLC) | E28: Mitsubishi PLC 비활성화
A29: 21 | D29: 특수 기능 - PLC Enable (Siemens PLC) | E29: Siemens PLC 활성화
A30: 22 | D30: 특수 기능 - PLC Disable (Siemens PLC) | E30: Siemens PLC 비활성화
A31: 23 | C31: 스크립트 | D31: 스크립트 함수 - IsTimeoutPLC (Serial PLC) | E31: 0:정상, 1:타임아웃 정상 표시
A32: 24 | D32: 스크립트 함수 - IsTimeoutPLC (Mitsubishi PLC) | E32: 0:정상, 1:타임아웃 정상 표시
A33: 25 | D33: 스크립트 함수 - IsTimeoutPLC (Siemens PLC) | E33: 0:정상, 1:타임아웃 정상 표시
A34: 26 | B34: N:N 통신 | C34: 시리얼 MBUS(XGB PLC) | D34: RS232 시리얼 통신 | E34: PLC 통신 정상 | G34: 개선 필요 | H34: #22928
A35: 27 | D35: MBUS 서버 통신 | E35: MBUS 서버 HMI 통신 정상
A36: 28 | D36: MBUS 클라이언트 통신 | E36: MBUS 클라이언트 HMI 통신 정상
A37: 29 | D37: MBUS 비트 램프 동작 | E37: PLC 래더 동작에 의한 비트 램프 순차 동작
A38: 30 | D38: MBUS 모멘터리 스위치 동작 | E38: 모멘터리 스위치 동작 시, 워드 데이터 읽기 동작 정상
A39: 31 | D39: MBUS Word 데이터 통신 | E39: HMI 스크립트에 의한 워드 데이터 쓰기 동작 정상
A40: 32 | C40: 이더넷 Mitsubishi PLC | D40: 주소 기반 PLC 통신 테스트 | E40: PLC 통신 정상
A41: 33 | D41: 주소 기반 PLC 비트 램프 통신 | E41: PLC 래더 동작에 의한 비트 램프 순차 동작
A42: 34 | D42: 주소 기반 PLC 모멘터리 스위치 | E42: 모멘터리 스위치 동작 시, 워드 데이터 읽기 동작 정상
A43: 35 | D43: 주소 기반 PLC Word 데이터 통신 | E43: HMI 스크립트에 의한 Word 데이터 쓰기 동작 정상
...

Sheet 경보
B2: 테스트 모델 | C2: TOPRD1240+TOPRP50D | F2: 정상 동작 | G2: 이상 발견 | H2: 개선 필요
B3: TDS 버전 | C3: =(표지!C6) -> 1.4.13.43 | F3: =IF(G2<>"", TEXT(COUNTIF(G9:G9957, "*" & F2 & "*") / COUNTA(A9:A957), "0.0%"), "") -> 0.0% | G3: =IF(G2<>"", TEXT(COUNTIF(G9:G9958, "*" & G2 & "*") / COUNTA(A9:A9958), "0.0%"), "") -> 0.0% | H3: =IF(H2<>"", TEXT(COUNTIF(G9:G9958, "*" & H2 & "*") / COUNTA(A9:A9958), "0.0%"), "") -> 0.0%
B4: 테스트 일자 | C4: 46239 | F4: 테스트 완료
B5: 작업자 | C5: =(표지!D15) -> 김현상 | F5: =TEXT(COUNTA(G9:G9957) / COUNTA(A9:A9958), "0.0%") -> 0.0%
A7: No | B7: 카테고리 | C7: 항목 | D7: 테스트 동작 | E7: 기대 결과 | G7: 테스트 결과 | H7: 비고
A9: 1 | B9: 경보 | C9: 기본 동작 | D9: 조건 확장 사용 - 기본 비트 동작 조건 | E9: 비트 조건 경보 발생
A10: 2 | D10: 조건 확장 사용 - 워드 동작 조건 | E10: 워드 조건 경보 발생
A11: 3 | D11: 글로벌 경보로 사용 | E11: 글로벌 경보 발생
A12: 4 | D12: 데이터 샘플링 사용 - Occur | E12: 워드 경보 발생 시, 워드 데이터 표시
A13: 5 | D13: 데이터 샘플링 사용 - Recovery | E13: 비트 경보 해제 시, 1Cycle 표시
A14: 6 | D14: 그룹 조건 사용 | E14: 워드 경보그룹 조건 만족 시에만 경보 동작 (Alarm ON 버튼)
A15: 7 | D15: 확장 사용 - Occurrence | E15: M0F 경보 발생 시, 동작 실행 (1Cycle++)
A16: 8 | D16: 확장 사용 - PressEnter | E16: 워드 경보 선택 시, 동작 실행 (워드값 = 0)
A17: 9 | D17: 현재 경보 발생건수 기록 | E17: 워드 현재 경보 발생 건수 저장
A18: 10 | C18: 조치 사항 | D18: 조치 사항 - Base Screen | E18: M0 경보 클릭 시, 화면 이동
A19: 11 | D19: 조치 사항 - 번호 저장 - 발생시 저장 | E19: M0 경보 발생 시, 해당 조치사항 번호 저장
A20: 12 | D20: 조치 사항 - Window | E20: M1 경보 클릭 시, 윈도우 화면 호출
A21: 13 | D21: 조치 사항 - 표시 제한 시간 설정 | E21: M1 경보 조치 사항 실행 후, 동작 복귀
A22: 14 | D22: 조치 사항 - 번호 저장 - 확인시 저장 | E22: M1 조치 사항 동작 시, 해당 조치사항 번호 저장
A23: 15 | D23: 조치 사항 - Image | E23: M2 경보 클릭 시, 이미지 호출
A24: 16 | D24: 조치 사항 - Text | E24: M3 경보 클릭 시, 텍스트 호출
A25: 17 | D25: 조치 사항 - PDF | E25: M4 경보 클릭 시, PDF 호출
A26: 18 | D26: 조치 사항 - PDF Ext - Page | E26: M5 경보 클릭 시, PDF 설정 페이지 호출
A27: 19 | D27: 조치 사항 - PDF Ext - Keyword | E27: M6 경보 클릭 시, PDF 설정 키워드 호출
A28: 20 | D28: 조치 사항 - PDF Ext - Page + Keyword | E28: M7 경보 클릭 시, PDF 설정 페이지의 키워드 호출
A29: 21 | C29: 경보 데이터 관리 | D29: 경보 - 내보내기 | E29: .halm 파일 생성
A30: 22 | D30: 경보 - 가져오기 | E30: .halm 파일 불러오기 정상
A31: 23 | D31: 경보 - CSV 내보내기 | E31: CSV 파일 생성
A32: 24 | D32: 경보 - CSV 가져오기 | E32: CSV 파일 불러오기 정상
A33: 25 | C33: 경보 뷰 오브젝트 | D33: 경보 뷰 오브젝트 - 키 - Delete | E33: 선택 경보 알람 이력 삭제
A34: 26 | D34: 경보 뷰 오브젝트 - 키 - Delete All | E34: 모든 경보 이력 삭제
A35: 27 | D35: 경보 뷰 오브젝트 - 키 - Clear Occur | E35: 선택 경보 알람 발생 횟수 초기화
A36: 28 | D36: 경보 뷰 오브젝트 - 키 - Clear Occur All | E36: 모든 경보 발생 횟수 초기화
A37: 29 | D37: 경보 뷰 오브젝트 - 키 - Confirm | E37: 선택 경보 확인
A38: 30 | D38: 경보 뷰 오브젝트 - 키 - Confirm All | E38: 모든 경보 확인
A39: 31 | D39: 경보 뷰 오브젝트 - 키 - Solution | E39: 선택 경보 조치사항 동작
A40: 32 | D40: 경보 뷰 오브젝트 - 키 - Data Search | E40: 선택 날짜의 경보 데이터 조회
A41: 33 | D41: 경보 뷰 오브젝트 - 키 - Statistics View | E41: 경보 통계 뷰어 호출
A42: 34 | D42: 경보 뷰 오브젝트 - 키 - Current Alarm | E42: 현재 발생중인 경보만 조회
A43: 35 | D43: 경보 뷰 오브젝트 - 키 - Today | E43: 오늘 날짜의 경보 데이터 조회
...

Sheet 로그
B2: 테스트 모델 | C2: TOPRT1550W | F2: 정상 동작 | G2: 이상 발견 | H2: 개선 필요
B3: TDS 버전 | C3: =(표지!C6) -> 1.4.13.43 | F3: =IF(G2<>"", TEXT(COUNTIF(G9:G9945, "*" & F2 & "*") / COUNTA(A9:A945), "0.0%"), "") -> 0.0% | G3: =IF(G2<>"", TEXT(COUNTIF(G9:G9946, "*" & G2 & "*") / COUNTA(A9:A9946), "0.0%"), "") -> 0.0% | H3: =IF(H2<>"", TEXT(COUNTIF(G9:G9946, "*" & H2 & "*") / COUNTA(A9:A9946), "0.0%"), "") -> 0.0%
B4: 테스트 일자 | C4: 46239 | F4: 테스트 완료
B5: 작업자 | C5: =(표지!D16) -> 김현상 | F5: =TEXT(COUNTA(G9:G9945) / COUNTA(A9:A9946), "0.0%") -> 0.0%
A7: No | B7: 카테고리 | C7: 항목 | D7: 테스트 동작 | E7: 기대 결과 | G7: 테스트 결과 | H7: 비고
A9: 1 | B9: 로그 | C9: 비순차 주소 로그 동작 | D9: 주소 블록 - 비순차 - 데이터 타입 DEC | E9: 로그 조건 만족 시, 데이터 생성
A10: 2 | D10: 주소 블록 - 비순차 - 데이터 타입 UDEC (소수점 자리 2 설정) | E10: 로그 조건 만족 시, 데이터 생성
A11: 3 | D11: 주소 블록 - 비순차 - 데이터 타입 HEX | E11: 로그 조건 만족 시, 데이터 생성
A12: 4 | D12: 주소 블록 - 비순차 - 데이터 타입 FLOAT (소수점 자리 2 설정) | E12: 로그 조건 만족 시, 데이터 생성
A13: 5 | D13: 주소 블록 - 비순차 - 데이터 타입 ASCII (문자열 길이 20 설정) | E13: 로그 조건 만족 시, 데이터 생성
A14: 6 | D14: 주소 블록 - 비순차 - 데이터 타입 BCD | E14: 로그 조건 만족 시, 데이터 생성
A15: 7 | C15: 심볼 주소 로그 동작 | D15: 주소 블록 - 심볼 - 데이터 타입 DEC | E15: 로그 조건 만족 시, 데이터 생성
A16: 8 | D16: 주소 블록 - 심볼 - 데이터 타입 UDEC (소수점 자리 2 설정) | E16: 로그 조건 만족 시, 데이터 생성
A17: 9 | D17: 주소 블록 - 심볼 - 데이터 타입 HEX | E17: 로그 조건 만족 시, 데이터 생성
A18: 10 | D18: 주소 블록 - 심볼 - 데이터 타입 FLOAT (소수점 자리 2 설정) | E18: 로그 조건 만족 시, 데이터 생성
A19: 11 | D19: 주소 블록 - 심볼 - 데이터 타입 ASCII (문자열 길이 20 설정) | E19: 로그 조건 만족 시, 데이터 생성
A20: 12 | D20: 주소 블록 - 심볼 - 데이터 타입 BCD | E20: 로그 조건 만족 시, 데이터 생성
A21: 13 | C21: 로그 조건 | D21: 로그 조건 - 인터벌 동작 (비순차) | E21: 인터벌 1초 조건으로 로그 데이터 생성
A22: 14 | D22: 로그 - 통신 주기 적용 (비순차 2s) | E22: 데이터 2초 주기로 데이터 갱신
A23: 15 | D23: 로그 조건 - 기록 개수 설정 (심볼) | E23: 조건 만족 시, 로그 데이터 2개 생성
A24: 16 | D24: 로그 - 조건 만족 시에만 통신 (심볼) | E24: 로그 뷰 오브젝트 데이터 생성
A25: 17 | C25: 로그 데이터 관리 | D25: 로그 - 내보내기 | E25: .hlog 파일 생성
A26: 18 | D26: 로그 - 가져오기 | E26: .hlog 파일 불러오기 정상
A27: 19 | C27: 로그 뷰 오브젝트 | D27: 로그 뷰 오브젝트 - 키 - Data Search | E27: 선택 날짜의 로그 데이터 조회
A28: 20 | D28: 로그 뷰 오브젝트 - 키 - View Clear | E28: 로그 뷰 오브젝트 화면 클리어
A29: 21 | D29: 로그 뷰 오브젝트 - 키 - Today | E29: 오늘 날짜의 로그 데이터 조회
A30: 22 | D30: 로그 뷰 오브젝트 - 키 - History | E30: 로그 데이터 전체 조회
A31: 23 | D31: 로그 뷰 오브젝트 - 키 - File | E31: SD 카드에 백업된 로그 파일 조회
A32: 24 | C32: 로그 백업 | D32: 로그 백업 설정 - SD 카드 - 오래된 파일 삭제 단위 (30%) | E32: 로그 100개 저장 시, 30% 데이터 SD 카드 백업
A33: 25 | D33: 로그 백업 - 백업 조건 사용 (심볼) | E33: 백업 조건 만족 시, SD 카드 백업
A34: 26 | D34: 로그 백업 - 로그 파일명 변경시 백업 (비순차) | E34: 날짜 변경 시, SD 카드 백업
A35: 27 | D35: 로그 백업 - 로그 파일명 변경시 백업 - 분할 저장 | E35: 분잘 저장 데이터 변경 시, SD 카드 백업
A36: 28 | D36: 특수 기능 - Logging CSV Export - Internel Memory | E36: eMMC 메모리에 로그 백업 (데이터 유지)
A37: 29 | D37: 특수 기능 - Logging CSV Export - SD Cartd | E37: SD 카드에 로그 백업 (데이터 유지)
A38: 30 | D38: 특수 기능 - Logging CSV Export - USB | E38: USB 메모리에 로그 백업 (데이터 유지)
A39: 31 | D39: 특수 기능 - Storage - SD Update | E39: SD 카드에 모든 로그 백업 후, 백업된 데이터 삭제
A40: 32 | D40: USB - Global Data - Log Upload | E40: USB 메모리에 로그 백업 (데이터 유지)
A41: 33 | C41: 기타 | D41: 특수 기능 - Log Clear | E41: HMI 경보 데이터 삭제
A42: 34 | D42: 메뉴 화면 - 제어판 - 초기화 - 로그 데이터 삭제 | E42: HMI 로그 데이터 삭제
A43: 35 | C43: 데이터셋 | D43: 데이터셋 - 갱신 | E43: 갱신 날짜 시간 기준 로그 개수 조회
...

Sheet 레시피
B2: 테스트 모델 | C2: TOPRT1550W | F2: 정상 동작 | G2: 이상 발견 | H2: 개선 필요
B3: TDS 버전 | C3: =(표지!C6) -> 1.4.13.43 | F3: =IF(G2<>"", TEXT(COUNTIF(G9:G9943, "*" & F2 & "*") / COUNTA(A9:A943), "0.0%"), "") -> 0.0% | G3: =IF(G2<>"", TEXT(COUNTIF(G9:G9944, "*" & G2 & "*") / COUNTA(A9:A9944), "0.0%"), "") -> 0.0% | H3: =IF(H2<>"", TEXT(COUNTIF(G9:G9944, "*" & H2 & "*") / COUNTA(A9:A9944), "0.0%"), "") -> 0.0%
B4: 테스트 일자 | C4: 46239 | F4: 테스트 완료
B5: 작업자 | C5: =(표지!D17) -> 김현상 | F5: =TEXT(COUNTA(G9:G9943) / COUNTA(A9:A9944), "0.0%") -> 0.0%
A7: No | B7: 카테고리 | C7: 항목 | D7: 테스트 동작 | E7: 기대 결과 | G7: 테스트 결과 | H7: 비고
A9: 1 | B9: 레시피 | C9: 레시피 데이터 관리 | D9: 레시피 - 내보내기 | E9: .hrcp 파일 생성
A10: 2 | D10: 레시피 - 가져오기 | E10: .hrcp 파일 불러오기 정상
A11: 3 | D11: 레시피 - CSV 내보내기 | E11: CSV 파일 생성
A12: 4 | D12: 레시피 - CSV 가져오기 | E12: CSV 파일 불러오기 정상
A13: 5 | C13: 레시피 데이터 | D13: 파라미터 다운로드 | E13: 파라미터 데이터 다운로드
A14: 6 | D14: 파라미터 다운로드 완료 비트 | E14: 파라미터 데이터 다운로드 조건 만족 시 ON
A15: 7 | D15: 파라미터 업로드 | E15: 파리미터 데이터 업로드
A16: 8 | D16: 파라미터 업로드 완료 비트 | E16: 파라미터 데이터 업로드 조건 만족 시 ON
A17: 9 | D17: 기본 데이터 불러오기 사용 | E17: 초기 파라미터 값 복귀
A18: 10 | D18: 기본 데이터 불러오기 완료 비트 | E18: 기본 데이터 불러오기 조건 만족 시 ON
A19: 11 | C19: 레시피 전송 | D19: 전송 옵션 - 데이터 덮어쓰기 | E19: TDS에 설정된 레시피 데이터 적용
A20: 12 | C20: 레시피 파일 저장 | D20: CSV 파일 저장 | E20: CSV 파일 생성
A21: 13 | D21: 파일번호 사용 - CSV 파일 저장 | E21: 설정한 번호가 포함된 CSV 파일 생성
A22: 14 | D22: CSV 파일 저장 완료 비트 | E22: CSV 파일 저장 조건 만족 시 ON
A23: 15 | D23: QR 코드 파일 저장 | E23: QR 코드 파일 생성
A24: 16 | D24: QR 코드 파일 저장 완료 비트 | E24: QR 코드 파일 저장 조건 만족 시 ON
A25: 17 | C25: 레시피 파일 불러오기 | D25: CSV 파일 불러오기 | E25: CSV 파일 불러오기
A26: 18 | D26: 파일번호 사용 - CSV 파일 불러오기 | E26: 설정한 번호가 포함된 CSV 파일 불러오기
A27: 19 | D27: CSV 파일 불러오기 완료 비트 | E27: CSV 파일 불러오기 조건 만족 시 ON
A28: 20 | D28: QR 코드 파일 불러오기 | E28: QR 코드 파일 불러오기
A29: 21 | D29: QR 코드 파일 불러오기 완료 비트 | E29: QR 코드 파일 불러오기 조건 만족 시 ON
A30: 22 | C30: 레시피 에디터 | D30: 특수 기능 - Recipe Editor Call | E30: 레시피 에디터 호출
A31: 23 | D31: Import | E31: 레시피 CSV 파일 불러오기
A32: 24 | D32: Export | E32: 레시피 CSV 파일 내보내기
A33: 25 | D33: 아이템 번호 - Download | E33: 선택한 아이템 번호의 파라미터 데이터 쓰기
A34: 26 | D34: 아이템 번호 - Upload | E34: 파리미터 주소값으로 부터 선택한 아이템 번호로 읽기
A35: 27 | D35: 아이템 추가 버튼 | E35: 아이템 삭제 후, 추가
A36: 28 | D36: 아이템 삭제 버튼 | E36: 선택한 아이템 삭제
A37: 29 | D37: 데이터 전체 삭제(Clear) 버튼 | E37: 전체 데이터 삭제
A38: 30 | D38: 데이터 리셋(Reset) 버튼 | E38: 파라미터 값 복귀
A39: 31 | D39: 데이터 검색(Search) 버튼 | E39: 설정한 아이템, 파라미터 검색
A40: 32 | C40: 기타 | D40: 메뉴 화면 - 제어판 - 초기화 - 레시피 데이터 삭제 | E40: 초기 파라미터 값 복귀

Sheet 문자열, 다국어
B2: 테스트 모델 | C2: TOPRT1550W | F2: 정상 동작 | G2: 이상 발견 | H2: 개선 필요
B3: TDS 버전 | C3: =(표지!C6) -> 1.4.13.43 | F3: =IF(G2<>"", TEXT(COUNTIF(G9:G9932, "*" & F2 & "*") / COUNTA(A9:A932), "0.0%"), "") -> 0.0% | G3: =IF(G2<>"", TEXT(COUNTIF(G9:G9933, "*" & G2 & "*") / COUNTA(A9:A9933), "0.0%"), "") -> 0.0% | H3: =IF(H2<>"", TEXT(COUNTIF(G9:G9933, "*" & H2 & "*") / COUNTA(A9:A9933), "0.0%"), "") -> 0.0%
B4: 테스트 일자 | C4: 46239 | F4: 테스트 완료
B5: 작업자 | C5: =(표지!I13) -> 김현상 | F5: =TEXT(COUNTA(G9:G9932) / COUNTA(A9:A9933), "0.0%") -> 0.0%
A7: No | B7: 카테고리 | C7: 항목 | D7: 테스트 동작 | E7: 기대 결과 | G7: 테스트 결과 | H7: 비고
A9: 1 | B9: 문자열 | C9: 문자열 데이터 관리 | D9: 문자열 - 내보내기 | E9: .hstr 파일 생성
A10: 2 | D10: 문자열 - 가져오기 | E10: .hstr 파일 불러오기 정상
A11: 3 | D11: 문자열 - CSV 내보내기 | E11: CSV 파일 생성
A12: 4 | D12: 문자열 - CSV 가져오기 | E12: CSV 파일 불러오기 정상
A13: 5 | C13: 문자열 설정 | D13: 사용 여부 검사 | E13: 사용 여부 조회
A14: 6 | D14: 문자열 검색 | E14: 검색어 조회
A15: 7 | D15: 로그 - 컬럼 제목 - 문자열 테이블 | E15: 로그 뷰 오브젝트 컬럼 문자열 정상 표시
A16: 8 | D16: 경보 - 문자열 타입 - 문자열 테이블 | E16: 경보 뷰 오브젝트 메시지 문자열 정상 표시
A17: 9 | C17: 다국어 | D17: 언어 설정 - 다국어 추가 | E17: 다국어 테이블 활성화
A18: 10 | D18: 특수 주소 - MULTI_LANGUAGE | E18: 다국어 언어 변경
A19: 11 | C19: 문자열 변환 | D19: 도구 - 문자열 변환 - 문자 → 문자열 테이블 | E19: 문자 → 문자열 테이블 변환
A20: 12 | D20: 도구 - 문자열 변환 - 문자열 테이블 → 문자 | E20: 문자열 테이블 → 문자 변환
A21: 13 | C21: 메시지 뷰 | D21: 메시지 뷰 - 비트 - 직접 입력 | E21: 조건 만족 시, 문자열 데이터 표시
A22: 14 | D22: 메시지 뷰 - 비트 - 문자열 테이블 | E22: 조건 만족 시, 문자열 데이터 표시
A23: 15 | D23: 메시지 뷰 - 비트 - ON 주소 읽기 | E23: 조건 만족 시, 문자열 데이터 표시
A24: 16 | D24: 메시지 뷰 - 비트 - OFF 주소 읽기 | E24: 조건 만족 시, 문자열 데이터 표시
A25: 17 | D25: 메시지 뷰 - 워드 - 직접 입력 | E25: 조건 만족 시, 문자열 데이터 표시
A26: 18 | D26: 메시지 뷰 - 워드 - 문자열 테이블 | E26: 조건 만족 시, 문자열 데이터 표시
A27: 19 | D27: 메시지 뷰 - 워드 - ON 주소 읽기 | E27: 조건 만족 시, 문자열 데이터 표시
A28: 20 | D28: 메시지 뷰 - 워드 - OFF 주소 읽기 | E28: 조건 만족 시, 문자열 데이터 표시
A29: 21 | D29: 메시지 뷰 - 워드 가변 - 선택 고정 | E29: 조건 만족 시, 문자열 데이터 표시
A30: 22 | D30: 메시지 뷰 - 워드 가변 - 주소 가변 | E30: 조건 만족 시, 문자열 데이터 표시

Sheet 보안
B2: 테스트 모델 | C2: TOPRT1550W | F2: 정상 동작 | G2: 이상 발견 | H2: 개선 필요
B3: TDS 버전 | C3: =(표지!C6) -> 1.4.13.43 | F3: =IF(G2<>"", TEXT(COUNTIF(G9:G9943, "*" & F2 & "*") / COUNTA(A9:A943), "0.0%"), "") -> 0.0% | G3: =IF(G2<>"", TEXT(COUNTIF(G9:G9944, "*" & G2 & "*") / COUNTA(A9:A9944), "0.0%"), "") -> 0.0% | H3: =IF(H2<>"", TEXT(COUNTIF(G9:G9944, "*" & H2 & "*") / COUNTA(A9:A9944), "0.0%"), "") -> 0.0%
B4: 테스트 일자 | C4: 46239 | F4: 테스트 완료
B5: 작업자 | C5: =(표지!I14) -> 안소희 | F5: =TEXT(COUNTA(G9:G9943) / COUNTA(A9:A9944), "0.0%") -> 0.0%
A7: No | B7: 카테고리 | C7: 항목 | D7: 테스트 동작 | E7: 기대 결과 | G7: 테스트 결과 | H7: 비고
A9: 1 | B9: 보안 | C9: 프로젝트 | D9: 프로젝트 비밀번호 사용 (12Ab) | E9: TDS 프로젝트 열기 시, 비밀번호 요구
A10: 2 | C10: 관리자 비밀번호 | D10: 관리자 비밀번호 설정 - 작화 다운로드 (123) | E10: 다운로드 시, 비밀번호 요구
A11: 3 | D11: 관리자 비밀번호 설정 - 작화 업로드 | E11: 업로드 시, 비밀번호 요구
A12: 4 | D12: 관리자 비밀번호 설정 - 메뉴화면 제어판 | E12: HMI 메뉴 화면 또는 제어판 진입 시 비밀번호 요구
A13: 5 | C13: 계정 | D13: 보안 - 계정 + 비밀번호 - 사용자 입력 - QR 코드 로그인 | E13: QR 코드를 통한 로그인 성공
A14: 6 | D14: 보안 - 계정 + 비밀번호 - 주소 참조 | E14: 참조 주소에 따른 가변 비밀번호 로그인 성공
A15: 7 | D15: 사용자 관리 및 권한 - 사용자 권한 - 데이터 없음 | E15: 모든 시스템 권한 없음
A16: 8 | D16: 사용자 관리 및 권한 - 사용자 권한 - 데이터 보기 | E16: 시스템 권한 조회까지 허용
A17: 9 | D17: 사용자 관리 및 권한 - 사용자 권한 - 내보내기 | E17: 시스템 권한 내보내기까지 허용
A18: 10 | D18: 사용자 관리 및 권한 - 사용자 권한 - 삭제 | E18: 모든 시스템 권한 획득
A19: 11 | D19: 사용자 권한 - VNC 권한 없음 | E19: Top Remote View 접속 불가 (User1)
A20: 12 | D20: 사용자 권한 - VNC 권한 보기 | E20: Top Remote View 접속 및 제어 불가 (User2)
A21: 13 | D21: 사용자 권한 - VNC 권한 제어 | E21: Top Remote View 접속 및 제어 가능 (User3,4)
A22: 14 | C22: 보안 데이터 관리 | D22: 보안 - 내보내기 | E22: .hsec 파일 생성
A23: 15 | D23: 보안 - 가져오기 | E23: .hsec 파일 불러오기 정상
A24: 16 | C24: 특수 주소 | D24: 특수 주소 - SECURITY_LOGIN_LEVEL | E24: 현재 로그인 계정 레벨 표시
A25: 17 | D25: 특수 주소 - SECURITY_LOGIN_SECOND | E25: 미동작 시 로그인 유지 시간 정상 동작
A26: 18 | D26: 특수 주소 - SECURITY_PASSWORD_EXPDAY | E26: 비밀번호 유효한 날짜 정상 표시
A27: 19 | C27: 특수 기능 | D27: 특수 기능 - Get User ID | E27: 현재 로그인 중 ID 불러오기
A28: 20 | D28: 특수 기능 - Get User Name | E28: 현재 로그인 중 계정 이름 불러오기
A29: 21 | D29: 특수 기능 - Auto Login | E29: 설정 주소 데이터에 의한 로그인 성공
A30: 22 | D30: 특수 기능 - Password Change | E30: 비밀번호 변경 창 호출
A31: 23 | D31: 특수 기능 - User Manager Call - 관리자 외 계정 접속 | E31: User Manager Call 비활성화
A32: 24 | D32: 특수 기능 - User Manager Call - 관리자 계정 접속 | E32: User Manager Call 활성화
A33: 25 | D33: 특수 기능 - User Manager Call - 관리자 계정 접속 - 설정 변경 | E33: 변경 된 설정에 대한 보안 로그 기록
A34: 26 | C34: 스크립트 함수 | D34: 스크립트 함수 - Add User | E34: HMI 운전 중 계정 추가
A35: 27 | D35: 스크립트 함수 - Export User Info From CSV | E35: 계정 정보 CSV 파일 추출
A36: 28 | D36: 스크립트 함수 - Import User Info From CSV | E36: CSV 파일로 부터 계정 정보 가져오기
A37: 29 | C37: 오브젝트 | D37: 오브젝트 - 보안 레벨 설정 | E37: 보안 레벨 미달 시, 계정 제어 불가
A38: 30 | D38: 오브젝트 - 보안 레벨 설정 + 미달 시 숨김 처리 설정 | E38: 보안 레벨 미달 시, 오브젝트 숨김
A39: 31 | C39: 보안 로그 | D39: 오브젝트 - 보안 로그 생성 | E39: 제어 동작에 대한 보안 로그 생성
A40: 32 | D40: 오브젝트 - 보안 로그 생성 + 메모 등록 | E40: 메모 정보가 포함된 보안 로그 생성
A41: 33 | D41: 변경 이력 및 추적 설정 - 보안 로그 생성 | E41: 이전 값, 변경 값에 대한 정보가 포함된 보안 로그 생성

Sheet 전송
B2: 테스트 모델 | C2: TOPRP20-TOPRD1220X | F2: 정상 동작 | G2: 이상 발견 | H2: 개선 필요
B3: TDS 버전 | C3: =(표지!C6) -> 1.4.13.43 | F3: =IF(G2<>"", TEXT(COUNTIF(G9:G9948, "*" & F2 & "*") / COUNTA(A9:A948), "0.0%"), "") -> 0.0% | G3: =IF(G2<>"", TEXT(COUNTIF(G9:G9949, "*" & G2 & "*") / COUNTA(A9:A9949), "0.0%"), "") -> 0.0% | H3: =IF(H2<>"", TEXT(COUNTIF(G9:G9949, "*" & H2 & "*") / COUNTA(A9:A9949), "0.0%"), "") -> 0.0%
B4: 테스트 일자 | C4: 46237 | F4: 테스트 완료
B5: 작업자 | C5: =(표지!I15) -> 안소희 | F5: =TEXT(COUNTA(G9:G9948) / COUNTA(A9:A9949), "0.0%") -> 0.0%
A7: No | B7: 카테고리 | C7: 항목 | D7: 테스트 동작 | E7: 기대 결과 | G7: 테스트 결과 | H7: 비고
A9: 1 | B9: 이더넷 | C9: 다운로드 | D9: 빌드 및 전송 - 이더넷 연결 - 다운로드 | E9: 다운로드 완료
A10: 2 | D10: 빌드 및 전송 - 멀티 이더넷 연결 - 다운로드 | E10: 다운로드 완료
A11: 3 | C11: 업로드 | D11: 데이터 업로드 | E11: TDS 업로드 완료
A12: 4 | B12: USB | C12: 다운로드 | D12: 빌드 및 전송 - USB 연결 - 다운로드 | E12: 다운로드 완료
A13: 5 | C13: 업로드 | D13: 데이터 업로드 | E13: TDS 업로드 완료
A14: 6 | B14: USB 메모리 | C14: 업로드 | D14: HBZ Upload | E14: HBZ 업로드 완료
A15: 7 | D15: 프로젝트 업로드 | E15: TDS 업로드 완료
A16: 8 | B16: 기타 | C16: 전송 | D16: 화면 전송 | E16: 화면 다운로드 완료
A17: 9 | C17: HBZ 파일 | D17: 전송용 파일 만들기(OS 포함) - 프로젝트 파일 전송 | E17: OS 버전 적용 다운로드 완료
A18: 10 | D18: 전송용 파일 만들기(OS 미포함) - 프로젝트 파일 전송 | E18: HMI OS 버전 유지 다운로드 완료
A19: 11 | C19: 프로젝트 비교 | D19: 도구 - 프로젝트 비교 | E19: 프로젝트 비교 완료
A20: 12 | C20: 파일 비교 | D20: 빌드 및 전송 - 파일 비교 | E20: 파일 비교 완료
A21: 13 | C21: 자동 시간 동기화 | D21: 빌드 옵션 설정 - 자동 시간 동기화 체크 - 다운로드 | E21: PC 시간 적용 완료
A22: 14 | C22: TDZ | D22: 프로젝트 속성 - 업로드 시 HMI 설정 값 가져오기 체크 - 다운로드 - 업로드 | E22: HMI 설정값이 포함된 TDZ 업로드
A23: 15 | C23: 데이터 | D23: 로그 업로드 | E23: 로그 데이터 업로드
A24: 16 | D24: 경보 업로드 | E24: 경보 데이터 업로드
A25: 17 | B25: 보안 | C25: 업로드 금지 | D25: 빌드 옵션 설정- 빌드 파일에 프로젝트 파일을 포함 체크 - 다운로드 | E25: TDS 업로드 불가 / HBZ 업로드 가능
A26: 18 | C26: HBZ 업로드 금지 | D26: 빌드 옵션 설정- HBZ 업로드 금지 체크 - 다운로드 | E26: TDS, HBZ 업로드 불가
A27: 19 | C27: 데이터 업로드 금지 | D27: 프로젝트 속성 - HMI 데이터 업로드 비활성화 체크 - TDS 로그 업로드 | E27: 로그 데이터 업로드 불가
A28: 20 | D28: 프로젝트 속성 - HMI 데이터 업로드 비활성화 체크 - TDS 경보 업로드 | E28: 경보 데이터 업로드 불가
A29: 21 | D29: 프로젝트 속성 - HMI 데이터 업로드 비활성화 체크 - USB 로그 업로드 | E29: 로그 데이터 업로드 불가
A30: 22 | D30: 프로젝트 속성 - HMI 데이터 업로드 비활성화 체크 - USB 경보 업로드 | E30: 경보 데이터 업로드 불가

Sheet VNC, FTP, 기타
B2: 테스트 모델 | C2: TOPRP20-TOPRD1220X | F2: 정상 동작 | G2: 이상 발견 | H2: 개선 필요
B3: TDS 버전 | C3: =(표지!C6) -> 1.4.13.43 | F3: =IF(G2<>"", TEXT(COUNTIF(G9:G9938, "*" & F2 & "*") / COUNTA(A9:A938), "0.0%"), "") -> 0.0% | G3: =IF(G2<>"", TEXT(COUNTIF(G9:G9939, "*" & G2 & "*") / COUNTA(A9:A9939), "0.0%"), "") -> 0.0% | H3: =IF(H2<>"", TEXT(COUNTIF(G9:G9939, "*" & H2 & "*") / COUNTA(A9:A9939), "0.0%"), "") -> 0.0%
B4: 테스트 일자 | C4: 46238 | F4: 테스트 완료
B5: 작업자 | C5: =(표지!I16) -> 안소희 | F5: =TEXT(COUNTA(G9:G9938) / COUNTA(A9:A9939), "0.0%") -> 0.0%
A7: No | B7: 카테고리 | C7: 항목 | D7: 테스트 동작 | E7: 기대 결과 | G7: 테스트 결과 | H7: 비고
A9: 1 | B9: 원격 HMI 서버 | C9: VNC | D9: 원격 HMI 서버 - VNC 서버 시작 - 클라이언트 접속 | E9: VNC 서버 접속
A10: 2 | D10: 원격 HMI 서버 - VNC 서버 시작 - 클라이언트 동작 제어 | E10: 클라이언트 동작 제어
A11: 3 | D11: 원격 HMI 서버 - 원격 제어 금지 | E11: 클라이언트 동작 제어 불가
A12: 4 | D12: 원격 HMI 서버 - 자동 시작 | E12: 전원 인가 시, VNC 서버 자동 실행
A13: 5 | C13: TOP Remote View | D13: TOP Remote View - VNC 서버 시작 - 클라이언트 접속 | E13: VNC 서버 접속
A14: 6 | D14: TOP Remote View - VNC 서버 시작 - 클라이언트 동작 제어 | E14: 클라이언트 동작 제어
A15: 7 | D15: TOP Remote View - 원격 제어 금지 | E15: 클라이언트 동작 제어 불가
A16: 8 | D16: TOP Remote View - 자동 시작 | E16: 전원 인가 시, VNC 서버 자동 실행
A17: 9 | B17: VNC | C17: VNC 뷰어 | D17: VNC 뷰어 - VNC 접속 | E17: VNC 클라이언트 접속
A18: 10 | D18: VNC 뷰어 - TOP Remote View - Admin 접속 | E18: TOP Remote View 관리자 접속
A19: 11 | D19: VNC 뷰어 - TOP Remote View - 보안 계정 접속 | E19: TOP Remote View 보안 계정 접속
A20: 12 | C20: TDS 특수 주소 | D20: 특수 주소 - REMOTE_CONTROL_BLOCK | E20: VNC 원격 제어 차단
A21: 13 | D21: 특수 주소 - VNC_USER_COUNT | E21: TOP Remote View 클라이언트 수
A22: 14 | B22: FTP | C22: FTP | D22: FTP 서버 - eMMC | E22: eMMC 접근 및 읽기
A23: 15 | D23: FTP 서버 - eMMC | E23: eMMC 접근 및 쓰기
A24: 16 | D24: FTP 서버 - SD 카드 | E24: SD 카드 접근 및 읽기
A25: 17 | D25: FTP - 접속 | E25: FTP 서버 접속
A26: 18 | B26: 프로젝트 옵션 | C26: 글로벌 잠금 옵션 | D26: 글로벌 터치 잠금 - 임시 비밀번호 | E26: 임시 비밀번호로 잠금 기능
A27: 19 | D27: 글로벌 터치 잠금 - 고정 비밀번호 (1234) | E27: 고정 비밀번호로 잠금 기능
A28: 20 | D28: 글로벌 잠금 - 비트 설정 (10초 후 자동 Off) | E28: 비트 값에 따른 글로벌 잠금 활성화
A29: 21 | D29: 글로벌 잠금 - 자동 잠금 시간 사용 (1분) | E29: 터치 입력이 없는 시점으로부터 설정한 시간이 지나면 잠금
A30: 22 | D30: PLC 터치 입력 사용 - 절대 좌표 | E30: PLC 값에 따른 절대 좌표 입력
A31: 23 | D31: PLC 터치 입력 사용 - 상대 좌표 | E31: PLC 값에 따른 상대 좌표 입력
A32: 24 | C32: 프로젝트 스타일 | D32: 프로젝트 스타일 | E32: 스타일 변경 주소에 따른 스타일을 변경
A33: 25 | C33: 스플래시 | D33: 스플래시 | E33: HMI 부팅 시 설정 이미지 표시
A34: 26 | B34: 메시지 | C34: 문자 | D34: 문자 보내기 - 직접 입력 (COOLSMS) | E34: COOL는 사이트 연동 문자 발송
A35: 27 | D35: 문자 보내기 - 직접 입력 (SOLAPI) | E35: SOLAPI 사이트 연동 문자 발송
A36: 28 | D36: 문자 보내기 - 경보 메시지 | E36: 경보 발생 시, 문자 발송
A37: 29 | C37: 이메일 | D37: 이메일 보내기 - 직접 입력 | E37: 설정 이메일 발송
A38: 30 | D38: 이메일 보내기 - 경보 메시지 | E38: 경보 발생 시, 이메일 발송
A39: 31 | B39: 제어판 | C39: 프로젝트 설정 | D39: 래치 사용(SYS50 ~ 59) | E39: 설정 범위 SYS 주소 래치 활성화
A40: 32 | B40: 초기화 | C40: SD 카드 초기화 | D40: SD 카드 복구 디스크로 초기화 | E40: OS 버전 정상 초기화

Sheet 테스트 결과
B2: No | C2: 카테고리 | D2: 작업자 | E2: 테스트 케이스 | F2: 테스트 결과 (정상 동작) | G2: 테스트 결과 (이상 발견) | H2: 테스트 결과 (개선 필요) | I2: 완료율 | J2: 통과율 | K2: 비고
B4: 1 | C4: PLC | D4: =INDIRECT("'"&C4&"'!C5") -> 정충영 | E4: =COUNT(INDIRECT("'"&C4&"'!A9:A9957")) -> 49 | F4: =COUNTIF(INDIRECT("'"&C4&"'!G9:G9956"), INDIRECT("'"&C4&"'!F2")) -> 0 | G4: =COUNTIF(INDIRECT("'"&C4&"'!G9:G9956"), INDIRECT("'"&C4&"'!G2")) -> 0 | H4: =COUNTIF(INDIRECT("'"&C4&"'!G9:G9956"), INDIRECT("'"&C4&"'!H2")) -> 3 | I4: =INDIRECT("'"&C4&"'!F5") -> 6.1% | J4: =(F4/E4) -> 0
B5: 2 | C5: TOP-VIEW | D5: =INDIRECT("'"&C5&"'!C5") -> 정충영 | E5: =COUNT(INDIRECT("'"&C5&"'!A9:A9957")) -> 57 | F5: =COUNTIF(INDIRECT("'"&C5&"'!G9:G9956"), INDIRECT("'"&C5&"'!F2")) -> 0 | G5: =COUNTIF(INDIRECT("'"&C5&"'!G9:G9956"), INDIRECT("'"&C5&"'!G2")) -> 0 | H5: =COUNTIF(INDIRECT("'"&C5&"'!G9:G9956"), INDIRECT("'"&C5&"'!H2")) -> 3 | I5: =INDIRECT("'"&C5&"'!F5") -> 5.3% | J5: =(F5/E5) -> 0
B6: 3 | C6: 경보 | D6: =INDIRECT("'"&C6&"'!C5") -> 김현상 | E6: =COUNT(INDIRECT("'"&C6&"'!A9:A9957")) -> 45 | F6: =COUNTIF(INDIRECT("'"&C6&"'!G9:G9956"), INDIRECT("'"&C6&"'!F2")) -> 0 | G6: =COUNTIF(INDIRECT("'"&C6&"'!G9:G9956"), INDIRECT("'"&C6&"'!G2")) -> 0 | H6: =COUNTIF(INDIRECT("'"&C6&"'!G9:G9956"), INDIRECT("'"&C6&"'!H2")) -> 0 | I6: =INDIRECT("'"&C6&"'!F5") -> 0.0% | J6: =(F6/E6) -> 0
B7: 4 | C7: 로그 | D7: =INDIRECT("'"&C7&"'!C5") -> 김현상 | E7: =COUNT(INDIRECT("'"&C7&"'!A9:A9957")) -> 52 | F7: =COUNTIF(INDIRECT("'"&C7&"'!G9:G9956"), INDIRECT("'"&C7&"'!F2")) -> 0 | G7: =COUNTIF(INDIRECT("'"&C7&"'!G9:G9956"), INDIRECT("'"&C7&"'!G2")) -> 0 | H7: =COUNTIF(INDIRECT("'"&C7&"'!G9:G9956"), INDIRECT("'"&C7&"'!H2")) -> 0 | I7: =INDIRECT("'"&C7&"'!F5") -> 0.0% | J7: =(F7/E7) -> 0
B8: 5 | C8: 레시피 | D8: =INDIRECT("'"&C8&"'!C5") -> 김현상 | E8: =COUNT(INDIRECT("'"&C8&"'!A9:A9957")) -> 32 | F8: =COUNTIF(INDIRECT("'"&C8&"'!G9:G9956"), INDIRECT("'"&C8&"'!F2")) -> 0 | G8: =COUNTIF(INDIRECT("'"&C8&"'!G9:G9956"), INDIRECT("'"&C8&"'!G2")) -> 0 | H8: =COUNTIF(INDIRECT("'"&C8&"'!G9:G9956"), INDIRECT("'"&C8&"'!H2")) -> 0 | I8: =INDIRECT("'"&C8&"'!F5") -> 0.0% | J8: =(F8/E8) -> 0
B9: 6 | C9: 문자열, 다국어 | D9: =INDIRECT("'"&C9&"'!C5") -> 김현상 | E9: =COUNT(INDIRECT("'"&C9&"'!A9:A9957")) -> 22 | F9: =COUNTIF(INDIRECT("'"&C9&"'!G9:G9956"), INDIRECT("'"&C9&"'!F2")) -> 0 | G9: =COUNTIF(INDIRECT("'"&C9&"'!G9:G9956"), INDIRECT("'"&C9&"'!G2")) -> 0 | H9: =COUNTIF(INDIRECT("'"&C9&"'!G9:G9956"), INDIRECT("'"&C9&"'!H2")) -> 0 | I9: =INDIRECT("'"&C9&"'!F5") -> 0.0% | J9: =(F9/E9) -> 0
B10: 7 | C10: 보안 | D10: =INDIRECT("'"&C10&"'!C5") -> 안소희 | E10: =COUNT(INDIRECT("'"&C10&"'!A9:A9957")) -> 33 | F10: =COUNTIF(INDIRECT("'"&C10&"'!G9:G9956"), INDIRECT("'"&C10&"'!F2")) -> 0 | G10: =COUNTIF(INDIRECT("'"&C10&"'!G9:G9956"), INDIRECT("'"&C10&"'!G2")) -> 0 | H10: =COUNTIF(INDIRECT("'"&C10&"'!G9:G9956"), INDIRECT("'"&C10&"'!H2")) -> 0 | I10: =INDIRECT("'"&C10&"'!F5") -> 0.0% | J10: =(F10/E10) -> 0
B11: 8 | C11: 전송 | D11: =INDIRECT("'"&C11&"'!C5") -> 안소희 | E11: =COUNT(INDIRECT("'"&C11&"'!A9:A9957")) -> 22 | F11: =COUNTIF(INDIRECT("'"&C11&"'!G9:G9956"), INDIRECT("'"&C11&"'!F2")) -> 0 | G11: =COUNTIF(INDIRECT("'"&C11&"'!G9:G9956"), INDIRECT("'"&C11&"'!G2")) -> 0 | H11: =COUNTIF(INDIRECT("'"&C11&"'!G9:G9956"), INDIRECT("'"&C11&"'!H2")) -> 0 | I11: =INDIRECT("'"&C11&"'!F5") -> 0.0% | J11: =(F11/E11) -> 0
B12: 9 | C12: VNC, FTP, 기타 | D12: =INDIRECT("'"&C12&"'!C5") -> 안소희 | E12: =COUNT(INDIRECT("'"&C12&"'!A9:A9957")) -> 32 | F12: =COUNTIF(INDIRECT("'"&C12&"'!G9:G9956"), INDIRECT("'"&C12&"'!F2")) -> 0 | G12: =COUNTIF(INDIRECT("'"&C12&"'!G9:G9956"), INDIRECT("'"&C12&"'!G2")) -> 0 | H12: =COUNTIF(INDIRECT("'"&C12&"'!G9:G9956"), INDIRECT("'"&C12&"'!H2")) -> 0 | I12: =INDIRECT("'"&C12&"'!F5") -> 0.0% | J12: =(F12/E12) -> 0
B13: 합 계 | E13: =SUM(E4:E12) -> 344 | F13: =SUM(F4:F12) -> 0 | G13: =SUM(G4:G12) -> 0 | H13: =SUM(H4:H12) -> 6 | I13: =((F13+G13+H13)/E13) -> 0.01744186 | J13: =(F13)/E13 -> 0
F14: =(F13/E13) -> 0 | G14: =(G13/E13) -> 0 | H14: =(H13/E13) -> 0.01744186

Sheet 작성 가이드
B3: TDS 소프트웨어 테스트 문서
B4: 개요 : 현장에서 사용하는 환경 구성이 아닌 단순히 각 기능들이 정상 동작하는지 검증하는 최소한의 단계로 상정하고 설계
B5: → PLC 통신이 중요하지 않은 항목은 내부 주소로 테스트 작화 구성
B7: 소프트웨어 테스트 작성가이드
B9: No | C9: 항목 | D9: 작성 방법
B10: 1 | C10: 표지 | D10: 2번 작업자 부분만 작성
B11: 2 | C11: 각 시트 | D11: 좌측 상단 테스트 모델(HMI)과 테스트 시작 일 작성 각 항목에 대한 테스트 결과 입력 테스트 결과 정상이 아닌 경우, 비고란에 레드마인 번호 기입
B12: 3 | C12: PLC / TOP-VIEW | D12: 6층 테스트 환경이 구성된 상태에서만 테스트 가능
B13: 4 | C13: 경보 / 로그 / 레시피 / 문자열, 다국어 | D13: PLC로 구성된 테스트 작화로 테스트 진행 (테스트 PLC는 작업자에게 전달)
B14: 5 | C14: 보안 / VNC, FTP, 기타 | D14: 내부 주소로 구성된 테스트 작화로 테스트 진행
B15: 6 | C15: 전송 | D15: 테스트 작화 없이 작업자가 가지고 있는 HMI로 테스트 진행
